Workbook
Name Recover: [1]Macro1!$A$45
Name TableName: "Dummy"

Sheet Aging Formulas
A2: Closing Month End Date | B2: =TODAY() -> 46251
A4: Aging Buckets
A5: Age | B5: Bucket
A6: 0 | B6: 0-30
A7: 1 | B7: 0-30
A8: 2 | B8: 0-30
A9: 3 | B9: 0-30
A10: 4 | B10: 0-30
A11: 5 | B11: 0-30
A12: 6 | B12: 0-30
A13: 7 | B13: 0-30
A14: 8 | B14: 0-30
A15: 9 | B15: 0-30
A16: 10 | B16: 0-30
A17: 11 | B17: 0-30
... A8575: 8569 | B8575: 365+

Sheet JAN-23
A3: Row Labels | B3: Sum of Entered Amount | F3: GL Balance per TB
A4: Federal Citizen Services | B4: 865908.8
A5: 12014 | B5: 865908.8 | F5: Difference | G5: =B35-G3 -> -1253619
A6: 1CDATA-21-C-0075 Reclassing streamline balance to correct PL - Should resolve in the next couple months. $374K CR in other BS Account | B6: 543000
A7: FCN EA Cost Deferral - CG emailed 11/15, possibly need vendor credit. Pricing correct see CMG email 11/17 | B7: 322908.8
A8: Federal Healthcare | B8: -1352553.6
A9: 11010 | B9: -1352553.6
A10: Awaiting fufillment - Closed Complete in August - Release? Check old cost recs AA sub for DCOGS Dec-21 thru present on public sector | B10: 52152.75
A11: Four Points Order on hold - Emailed Dawn 2/13/2023 - Check Cost Rec for reversal 2/17 | B11: 20953.35
A12: Orders on hold - follow up with team 10702660/10702659/10702554/10705836/10702668 | B12: 221281.44
A13: VA EA Deal | B13: -1646941.1
A14: Federal House | B14: 44929.56
A15: 11016 | B15: 44929.56
A16: PO 1CDATA-21-C-0075, to reverse US postal in February | B16: 44929.56
A17: Federal Intel | B17: 68161.14
A18: 12012 | B18: 68161.14
A19: Timing - RecVue Pending Credit - Follow up on credit | B19: 68161.14
A20: Federal Intel Moonshot | B20: -1100000
A21: 12022 | B21: -1100000
A22: Moonshot SAAS RecVue | B22: -1100000
A23: Federal Law Enforcement | B23: -41798.4
A24: 12013 | B24: -41798.4
A25: Monthly Timing - follow email 1/20 & 1/27 - followed up 2/13/2023 | B25: -41798.4
A26: Federal Navy | B26: 200826
A27: 11023 | B27: 200826
A28: Timing - Streamline FEDERAL RESOURCES PO 157803 | B28: 200826
A29: Federal Scientific | B29: 7355
A30: 12021 | B30: 7355
A31: Timing - Streamline CGI Federal PR20005283 | B31: 7355
A32: SLED Central | B32: 53552.52
A33: 13006 | B33: 53552.52
A34: Timing - Pending Credit - See email for pending Cisco Credit… Descrepancy on amount billed vs credited. Sitting in 24500 code to 50210 6k diff to SC | B34: 53552.52
A35: Grand Total | B35: -1253619

Sheet FEB-23
A3: Row Labels | B3: Sum of Entered Amount | F3: GL Balance per TB | G3: ='[2]Timing Variances'!$C$62 -> -1988221
A4: Federal Air Force | B4: 106212.6
A5: 11001 | B5: 106212.6 | F5: Difference | G5: =B35-G3 -> -2.7939677e-09
A6: (blank) | B6: 106212.6
A7: Federal Citizen Services | B7: -252091.2
A8: 12014 | B8: -252091.2
A9: FCN EA Cost Deferral - CG emailed 11/15, possibly need vendor credit. Pricing correct see CMG email 11/17 | B9: 322908.8
A10: (blank) | B10: -575000
A11: Federal COCOMs | B11: 335257.6
A12: 12015 | B12: 335257.6
A13: (blank) | B13: 335257.6
A14: Federal Healthcare | B14: -1214443.7
A15: 11010 | B15: -1214443.7
A16: Awaiting fufillment - Closed Complete in August - Release? Check old cost recs AA sub for DCOGS Dec-21 thru present on public sector | B16: 52152.75
A17: Orders on hold - follow up with team 10702660/10702659/10702554/10705836/10702668 | B17: 221281.44
A18: (blank) | B18: -1487877.9
A19: Federal House | B19: 575000
A20: 11016 | B20: 575000
A21: (blank) | B21: 575000
A22: Federal Intel | B22: 68161.14
A23: 12012 | B23: 68161.14
A24: Timing - RecVue Pending Credit - Follow up on credit | B24: 68161.14
A25: Federal Law Enforcement | B25: -41798.4
A26: 12013 | B26: -41798.4
A27: Monthly Timing - follow email 1/20 & 1/27 - followed up 2/13/2023 | B27: -41798.4
A28: Federal Navy | B28: 200826
A29: 11023 | B29: 200826
A30: Timing - Streamline FEDERAL RESOURCES PO 157803 | B30: 200826
A31: Federal Scientific | B31: -1765345
A32: 12021 | B32: -1765345
A33: Timing - Streamline CGI Federal PR20005283 | B33: 7355
A34: (blank) | B34: -1772700
A35: Grand Total | B35: -1988221

Sheet MAR-23
A3: Row Labels | B3: Sum of Entered Amount
A4: Federal Air Force | B4: 29762.6
A5: 11001 | B5: 29762.6
A6: (blank) | B6: 29762.6
A7: Federal Citizen Services | B7: -252091.2
A8: 12014 | B8: -252091.2
A9: FCN EA Cost Deferral - CG emailed 11/15, possibly need vendor credit. Pricing correct see CMG email 11/17 | B9: 322908.8
A10: Reclass between P&L | B10: -575000
A11: Federal COCOMs | B11: 335257.6
A12: 12015 | B12: 335257.6
A13: To defer cost on Customer PO 10000410, SO 10768674, Emailed Shelly on 2/23, 3/14 | B13: 369435.6
A14: To defer revenue & cost on Customer PO 10000410, SO 10230194 - Emailed Shelly on 2/22, 3/14 CUB 2173719 creating issue | B14: -34178
A15: Federal Healthcare | B15: -508197.14
A16: 11010 | B16: -508197.14
A17: 128k * 2 + 14k | B17: 270985
A18: Awaiting fufillment - Closed Complete in August - Release? Check old cost recs AA sub for DCOGS Dec-21 thru present on public sector | B18: 52152.75
A19: Defer Federal Health WWTINCSAAS924, PO 22P09282 | B19: 128000
A20: Reversed in April | B20: 456543
A21: Reversed in April - VA EA March AP Invoices | B21: -1415877.9
A22: Federal House | B22: 575000
A23: 11016 | B23: 575000
A24: Reclass between P&L | B24: 575000
A25: Federal Intel | B25: 80451.04
A26: 12012 | B26: 80451.04
A27: Timing - RecVue Pending Credit - Follow up on credit | B27: 68161.14
A28: (blank) | B28: 12289.9
A29: Federal Law Enforcement | B29: -32743.78
A30: 12013 | B30: -32743.78
A31: Monthly Timing - follow email 1/20 & 1/27 - followed up 2/13, 3/15, 4/14 | B31: -41798.4
A32: Needs to be reversed in April | B32: 9054.62
A33: Federal Navy | B33: 200826
A34: 11023 | B34: 200826
A35: Timing - Streamline FEDERAL RESOURCES PO 157803 - should reverse in May | B35: 200826
A36: Federal Navy NGEN | B36: 73709.27
A37: 11024 | B37: 73709.27
A38: Part of Inv Reserve in AR other account | B38: 73709.27
A39: Federal Scientific | B39: 7355
A40: 12021 | B40: 7355
A41: Timing - Streamline CGI Federal PR20005283 | B41: 7355
A42: Federal USACE | B42: -6022.36
...

Sheet MAY-23
A3: Row Labels | B3: Sum of Entered Amount
A4: Federal Air Force | B4: 29762.6
A5: (blank) | B5: 29762.6
A6: Federal Army Enterprise | B6: -183844.21
A7: (blank) | B7: -130197.21
A8: Sent Email for missing Cost in May 6/14/23 | B8: -53647 | D8: WWT PO 4183946 was matched but didn't transact on OPR missing 50,610k of cost. Drop Shipped org 39????????
A9: Federal Citizen Services | B9: 322908.8
A10: FCN EA Cost Deferral - CG emailed 11/15, possibly need vendor credit. Pricing correct see CMG email 11/17, 6/15 | B10: 322908.8 | D10: Emailed 6/15 - Pricing issue to determine additional billing to customer
A11: Federal COCOMs | B11: 335257.6
A12: To defer cost on Customer PO 10000410, SO 10768674, Emailed Shelly on 2/23, 3/14, 4/19, 6/15 - Jake is working on matching Hours completed with customer and IUB will be booked | B12: 335257.6 | D12: Jake V is working with Customer on services completed and matching hours. IUB should be booked to help offset issues with CUB.
A13: Federal Healthcare | B13: 99921.1
A14: Awaiting fufillment - Closed Complete in August - Release? Check old cost recs AA sub for DCOGS Dec-21 thru present on public sector | B14: 52152.75
A15: Awaiting fufillment, follow up with Dawn - Reversed in June | B15: 18800 | D15: Reversed in June
A16: Defer Federal Health WWTINCSAAS924, PO 22P09282 | B16: 398985 | D16: VA EA
A17: Reversing portion of VA EA related cost | B17: -370016.65 | D17: VA EA
A18: Federal Intel | B18: 80451.04
A19: Emailed 4/5 for missing Rev | B19: 12289.9
A20: Timing - RecVue Pending Credit - Follow up on credit | B20: 68161.14 | D20: Emailed 6/15/23 Jessica Laux & Karen Melton to see if there is a Credit from Cisco on WWTINCSAAS752 Invoice # 81025413 - Reverse it at later point confirm with molly
A21: Federal Law Enforcement | B21: -32743.78
A22: Monthly Timing - follow email 1/20 & 1/27 - followed up 2/13, 3/15, 4/14 | B22: -41798.4 | D22: Issue with Cost on WWT PO 4080608 missing from Vendor
A23: Reversed in June - Needs to be reversed in May | B23: 9054.62 | D23: Reversed in June
A24: Federal Navy | B24: 200826
A25: Timing - Streamline FEDERAL RESOURCES PO 157803 - should reverse in May | B25: 200826 | D25: Streamline - BL for later period
A26: Federal Navy NGEN | B26: 1553790.8
A27: Reversed in June - Part of Inv Reserve in AR other account | B27: 1553790.8 | D27: Working on JE's to move to Federal House offset in 130509
A28: Federal Scientific | B28: 7355
A29: Timing - Streamline CGI Federal PR20005283 | B29: 7355 | D29: Streamline
A30: SLED Central | B30: -45396.3
A31: PO P3152301398 SO 10764155 Expecting Cost in July | B31: -45396.3
A32: SLED Southeast | B32: -37685.19
A33: Cost Accrual - expected in October | B33: -37685.19
A34: Grand Total | B34: 2330603.4

Sheet July-23
A3: Row Labels | B3: Sum of Entered Amount
A4: Federal Air Force | B4: 29762.6
A5: (blank) | B5: 29762.6
A6: Federal Army Enterprise | B6: -53647
A7: Sent Email for missing Cost in May 6/14/23 | B7: -53647
A8: Federal Citizen Services | B8: -10602091 | D8: WWT PO 4183946 was matched but didn't transact on OPR missing 50,610k of cost. Drop Shipped org 39????????
A9: (blank) | B9: -10925000
A10: FCN EA Cost Deferral - CG emailed 11/15, possibly need vendor credit. Pricing correct see CMG email 11/17, 6/15 | B10: 322908.8 | D10: Emailed 6/15 - Pricing issue to determine additional billing to customer
A11: Federal COCOMs | B11: 335257.6
A12: To defer cost on Customer PO 10000410, SO 10768674, Emailed Shelly on 2/23, 3/14, 4/19, 6/15 - Jake is working on matching Hours completed with customer and IUB will be booked | B12: 335257.6 | D12: Jake V is working with Customer on services completed and matching hours. IUB should be booked to help offset issues with CUB.
A13: Federal Healthcare | B13: 52152.75
A14: Awaiting fufillment - Closed Complete in August - Release? Check old cost recs AA sub for DCOGS Dec-21 thru present on public sector | B14: 52152.75
A15: Federal Intel | B15: 80451.04 | D15: Reversed in June
A16: Emailed 4/5 for missing Rev | B16: 12289.9 | D16: VA EA
A17: Timing - RecVue Pending Credit - Follow up on credit | B17: 68161.14 | D17: VA EA
A18: Federal Law Enforcement | B18: 86843.47
A19: Monthly Timing - follow email 1/20 & 1/27 - followed up 2/13, 3/15, 4/14 | B19: -41798.4
A20: (blank) | B20: 128641.87 | D20: Emailed 6/15/23 Jessica Laux & Karen Melton to see if there is a Credit from Cisco on WWTINCSAAS752 Invoice # 81025413 - Reverse it at later point confirm with molly
A21: Federal Navy | B21: -77500
A22: (blank) | B22: -77500 | D22: Issue with Cost on WWT PO 4080608 missing from Vendor
A23: Federal Scientific | B23: 7355 | D23: Reversed in June
A24: Timing - Streamline CGI Federal PR20005283 | B24: 7355
A25: Federal Intel Moonshot | B25: 558594.33 | D25: Streamline - BL for later period
A26: (blank) | B26: 558594.33
A27: Grand Total | B27: -9582821.4 | D27: Working on JE's to move to Federal House offset in 130509
D29: Streamline

Sheet Aug-23
A3: Row Labels | B3: Sum of Entered Amount
A4: Federal Air Force | B4: 4762.6
A5: Ops Issue | B5: 29762.6 | D5: SO 10650154
A6: Finder's Fee | B6: -25000 | D6: Check request once paid.
A7: Federal Army Enterprise | B7: -53647
A8: Sent Email for missing Cost in May 6/14/23 | B8: -53647 | D8: WWT PO 4183946 was matched but didn't transact on OPR missing 50,610k of cost. Drop Shipped org 39????????
A9: Federal Citizen Services | B9: 322908.8
A10: FCN EA Cost Deferral - CG emailed 11/15, possibly need vendor credit. Pricing correct see CMG email 11/17, 6/15 | B10: 322908.8 | D10: Emailed 6/15 - Pricing issue to determine additional billing to customer
A11: Federal Healthcare | B11: 2141402.8
A12: Awaiting fufillment - Closed Complete in August - Release? Check old cost recs AA sub for DCOGS Dec-21 thru present on public sector | B12: 52152.75 | D12: Jake V is working with Customer on services completed and matching hours. IUB should be booked to help offset issues with CUB.
A13: Annual billing through RecVue awaiting RMA/RTV | B13: 2089250 | D13: Double check RMA/RTV. On cost side
A14: Federal Intel | B14: 80451.04
A15: Emailed 4/5 for missing Rev | B15: 12289.9
A16: Timing - RecVue Pending Credit - Follow up on credit | B16: 68161.14
A17: Federal Law Enforcement | B17: -17423.4
A18: Monthly Timing - follow email 1/20 & 1/27 - followed up 2/13, 3/15, 4/14 | B18: -41798.4
A19: Ops Issue | B19: 24375 | D19: SO 10944744 IUB
A20: Federal Navy | B20: 971656.3
A21: Replacement orders needing RMA/RTV | B21: 971656.3 | D21: SO 10941581 / 5
A22: Federal Scientific | B22: 7355 | D22: Issue with Cost on WWT PO 4080608 missing from Vendor
A23: Timing - Streamline CGI Federal PR20005283 | B23: 7355 | D23: Reversed in June
A24: Federal Intel Moonshot | B24: -85230.24
A25: Moonshot | B25: -85230.24 | D25: Streamline - BL for later period
A26: Federal Army/SOF House | B26: -1065122.5
A27: Reverse in September | B27: -1065122.5 | D27: Working on JE's to move to Federal House offset in 130509
A28: Grand Total | B28: 2307113.3
D29: Streamline

Sheet Sept-23
A3: Row Labels | B3: Sum of Entered Amount
A4: Federal Air Force | B4: -25292.18
A5: Ops Issue | B5: 29762.6 | D5: SO 10650154 | E5: Reverse in October
A6: Finder's Fee | B6: -30054.78 | D6: SO 1105877
A7: Reversed in October Finder's Fee - Check Request submitted should be reversed in October | B7: -25000 | D7: Reversed in October
A8: Federal Army Enterprise | B8: -53647
A9: Sent Email for missing Cost in May 6/14/23 | B9: -53647 | D9: WWT PO 4183946 was matched but didn't transact on OPR missing 50,610k of cost. Drop Shipped org 39???????? Rework needed.
A10: Federal Citizen Services | B10: 491772.46
A11: FCN EA Cost Deferral - CG emailed 11/15, possibly need vendor credit. Pricing correct see CMG email 11/17, 6/15 | B11: 322908.8
A12: Awaiting RMA/RTV rework Email from Angie H 10/11/23 Needs to be Released. | B12: 168863.66
A13: Federal Healthcare | B13: 52152.75
A14: Awaiting fufillment - Closed Complete in August - Release? Check old cost recs AA sub for DCOGS Dec-21 thru present on public sector | B14: 52152.75 | D14: SO 9796205 | E14: Needs more research
A15: Federal Intel | B15: 80451.04
A16: Emailed 4/5 for missing Rev | B16: 12289.9 | D16: SO 10805628 | E16: Need More research and follow up
A17: Timing - RecVue Pending Credit - Follow up on credit | B17: 68161.14
A18: Federal Law Enforcement | B18: -17423.4
A19: Monthly Timing - follow email 1/20 & 1/27 - followed up 2/13, 3/15, 4/14 | B19: -41798.4 | D19: Working with Julie on resulition
A20: Ops Issue | B20: 24375 | D20: Follow up with Tyler for resolution - from august
A21: Federal Navy | B21: 971656.3
A22: Replacement orders needing RMA/RTV | B22: 971656.3 | D22: SO 10941581 & 10941585 - August
A23: Federal Scientific | B23: 7355
A24: Timing - Streamline CGI Federal PR20005283 | B24: 133855 | D24: Needs to be reversed from timing. Nothing in BL - Reverse out in August
A25: Timing - Streamline CGI Federal PR20005283 - | B25: -126500 | D25: Needs to be reversed from timing. Nothing in BL - Reverse out in August
A26: Federal Intel Moonshot | B26: -1239252.6
A27: Moonshot - Needs research Material Distribution Report | B27: -85230.24 | D27: Material Distribution Report
A28: Reversed in October | B28: -1154022.3 | D28: Reversed in October
A29: SLED Southeast | B29: -1557.97
A30: Need Ticket for stuck SAAS AP invoice hit OPR but not GL | B30: -1557.97
A31: SLED PANYNJ NESS | B31: -81871.89
A32: Finder's Fee | B32: -81871.89
A33: Grand Total | B33: 184342.53

Sheet Oct-23
A3: Row Labels | B3: Sum of Entered Amount
A4: Federal Air Force | B4: -30054.78
A5: Reversed in November Finder's Fee - Check Request Processed 11/8 | B5: -30054.78 | D5: Reversed in November
A6: Federal Army Enterprise | B6: -53647 | D6: SO 1105877
A7: Sent Email for missing Cost in May 6/14/23 | B7: -53647 | D7: Working with Julie for resolution SO 10920127 / WWT PO 4183946 was matched but didn't transact on OPR missing 50,610k of cost. Drop Shipped org 39???????? Rework needed.
A8: Federal Citizen Services | B8: 322908.8
A9: FCN EA Cost Deferral - CG emailed 11/15, possibly need vendor credit. Pricing correct see CMG email 11/17, 6/15, 11/13 | B9: 322908.8 | D9: WWT cost was accurate and need update in extra qty should be billed to customer pricing issue SO 10537043
A10: Federal Healthcare | B10: 52152.75
A11: Needs to be Reversed out in November - Awaiting fufillment - Closed Complete in August - Release? Check old cost recs AA sub for DCOGS Dec-21 thru present on public sector | B11: 52152.75 | D11: Needs to be reversed out of timing. Confirm with Christine/Laura if we can take this to G/A
A12: Federal Intel | B12: 80451.04
A13: Emailed 4/5 for missing Rev | B13: 12289.9
A14: Timing - RecVue Pending Credit - Follow up on credit | B14: 68161.14 | D14: RecVue credit to use on future order?
A15: Federal Law Enforcement | B15: -17423.4
A16: Monthly Timing - follow email 1/20 & 1/27 - followed up 2/13, 3/15, 4/14 | B16: -41798.4 | D16: Working with Julie Cost changed to $0 and need rework or correction
A17: Reversed in November | B17: 24375 | D17: Reversed in November - Pick up in Prior month.
A18: Federal Navy | B18: 971656.3
A19: Replacement orders needing RMA/RTV emailed 10/19 & 11/14 | B19: 971656.3 | D19: RMA/RTV being processed not yet complete
A20: Federal Intel Moonshot | B20: -85230.24
A21: Reversed in November Moonshot - Needs research Material Distribution Report | B21: -85230.24 | D21: Reversed in November
A22: SLED Southeast | B22: 2675298.7
A23: Need Ticket for stuck SAAS AP invoice hit OPR but not GL | B23: -1557.97 | D23: Ticket needed for missing GL amount
A24: Waiting on IUB's to process - Emailed 11/14 | B24: 2676856.7 | D24: Awaiting IUB's on Bulk PO's
A25: SLED PANYNJ NESS | B25: -81871.89
A26: Finder's Fee - Awaiting Payment | B26: -81871.89 | D26: Finder's Fee
A27: SLED HI/Comm | B27: 187267.68
A28: Reversed in November | B28: 187267.68 | D28: Reversed in November
A29: Federal AF/DISA/DA House | B29: -771663.59
A30: Termination Fee to be paid by EOY | B30: -771663.59 | D30: Termination Fee check request to submitted to clear by EOY
A31: SLED Northeast | B31: -385157.57
A32: Finder's Fee - Awaiting Payment | B32: -385157.57 | D32: Finder's Fee
A33: Grand Total | B33: 2864686.8

Sheet NOV-23
A3: Row Labels | B3: Sum of Entered Amount
A4: Federal AF/DISA/DA House | B4: -771663.59
A5: Termination Fee to be paid by EOY | B5: -771663.59 | D5: Megan following up
A6: Federal Army Enterprise | B6: -53647
A7: Sent Email for missing Cost in May 6/14/23 | B7: -53647 | D7: SO 10920127 Emailed 10/26 & 12/19
A8: Federal Citizen Services | B8: 106778.22
A9: Accrued Missing WWT Cost PO 1CDATA-22-C-0113_3 for proper recognition | B9: -216130.58
A10: FCN EA Cost Deferral - CG emailed 11/15, possibly need vendor credit. Pricing correct see CMG email 11/17, 6/15, 11/13 | B10: 322908.8 | D10: SO 10537043 Latest email sent 11/15 & 12/19 - See PO 63353P email from Dawn | K10: 63550P
A11: Federal DOD House | B11: -1107269
A12: To be released in December | B12: -1107269 | D12: Reverse in December
A13: Federal Healthcare | B13: -75847.25
A14: Needs to be Reversed out in November - Awaiting fufillment - Closed Complete in August - Release? Check old cost recs AA sub for DCOGS Dec-21 thru present on public sector | B14: 52152.75 | D14: JE to be made to G/A by Christine
A15: Will offset in Decemeber Check other timing account | B15: -128000 | D15: Reverse in December
A16: Federal Intel | B16: 80451.04
A17: Emailed 4/5 for missing Rev | B17: 12289.9
A18: Timing - RecVue Pending Credit - Follow up on credit | B18: 68161.14 | D18: Emailed 6/15/23 Jessica Laux & Karen Melton to see if there is a Credit from Cisco on WWTINCSAAS752 Invoice # 81025413 - Reverse it at later point confirm with molly
A19: Federal Intel Moonshot | B19: -85230.24
A20: Moonshot - Needs research Material Distribution Report | B20: -85230.24 | D20: PO Receipt adj tied to a canceled SO in Dinga Linda SC - WWT PO 4031126 SO 10269777
A21: Federal Law Enforcement | B21: -41798.4
A22: Monthly Timing - follow email 1/20 & 1/27 - followed up 2/13, 3/15, 4/14 | B22: -41798.4 | D22: SO 10479984 - PO lines were received in at $0 in error, so the cost is incorrect. Need Avg cost adj follow up with Dan Besmer
A23: Federal Navy | B23: 971656.3
A24: Replacement orders needing RMA/RTV emailed 10/19 & 11/14 | B24: 971656.3 | D24: half the gear being returned.
A25: SLED Northeast | B25: -385157.57
A26: Finder's Fee - Awaiting Payment | B26: -385157.57 | D26: Finder's Fee - partially paid 8 invoices
A27: SLED PANYNJ NESS | B27: -81871.89
A28: Finder's Fee - Awaiting Payment | B28: -81871.89 | D28: Finder's Fee - Still not paid
A29: SLED Southeast | B29: 2739888.3
A30: Need Ticket for stuck SAAS AP invoice hit OPR but not GL | B30: -1557.97
A31: Waiting on IUB's to process - Emailed 11/14 | B31: 2741446.3 | D31: Reverse 1M of WWT cost from IUB's released in December
A32: Grand Total | B32: 1296288.9

Sheet DEC-23
A3: Row Labels | B3: Sum of Entered Amount
A4: Federal AF/DISA/DA House | B4: -771663.59
A5: Termination Fee to be paid by EOY | B5: -771663.59
A6: Federal Air Force | B6: -46391
A7: Finder's Fee - Awaiting Payment | B7: -46391 | D7: Finder's Fee
A8: Federal Army Enterprise | B8: -53647
A9: Sent Email for missing Cost in May 6/14/23 | B9: -53647 | D9: Ops issue due to bring material back on hand @ $0
A10: Federal Citizen Services | B10: 106778.22
A11: Accrued Missing WWT Cost PO 1CDATA-22-C-0113_3 for proper recognition | B11: -216130.58
A12: FCN EA Cost Deferral - CG emailed 11/15, possibly need vendor credit. Pricing correct see CMG email 11/17, 6/15, 11/13 | B12: 322908.8 | D12: SO 10537043
A13: Federal COCOMs | B13: 235689.25
A14: Avg cost correction | B14: 235689.25 | D14: Avg cost correction SO 10811548 Part GSCUSTFCD PO 1268959 - Run material distrubition on Part #
A15: Federal Healthcare | B15: -598997
A16: EA Aqueon | B16: -456012 | D16: To be corrected in January.
A17: Reverse in January | B17: -14985 | D17: Reversed in January
A18: Will offset in Decemeber Check other timing account | B18: -128000 | D18: Dig into 128k and OPR for correction.
A19: Federal Intel | B19: 137062.42
A20: Emailed 4/5 for missing Rev | B20: 12289.9 | D20: SO 10805628
A21: Ops issue needs rework | B21: 56611.38 | D21: SO 11258948 - Needs research and followup
A22: Timing - RecVue Pending Credit - Follow up on credit | B22: 68161.14
A23: Federal Intel Moonshot | B23: -85230.24
A24: Moonshot - Needs research Material Distribution Report | B24: -85230.24 | D24: WWTPO 4031126 SO 10269777 hitting Dinga Linda SC / Move to Main SC in January
A25: Federal Law Enforcement | B25: -41798.4
A26: Monthly Timing - follow email 1/20 & 1/27 - followed up 2/13, 3/15, 4/14 | B26: -41798.4 | D26: SO 10479984
A27: SLED Northeast | B27: -385157.57
A28: Finder's Fee - Awaiting Payment | B28: -385157.57 | D28: Finder's Fee - Check Request or possible invoice.
A29: SLED PANYNJ NESS | B29: -81871.89
A30: Finder's Fee - Awaiting Payment | B30: -81871.89 | D30: To be reversed in January.
A31: SLED Southeast | B31: 1335237.3
A32: Need Ticket for stuck SAAS AP invoice hit OPR but not GL | B32: -1557.97
A33: Waiting on IUB's to process - Emailed 11/14 | B33: 1336795.3 | D33: Waiting rest of IUB's to process next week in January
A34: Grand Total | B34: -249989.47

Sheet Jan-24
A4: Row Labels | B4: Sum of Entered Amount
A5: Federal AF/DISA/DA House | B5: -771663.59
A6: Termination Fee to be paid by EOY | B6: -771663.59
A7: Federal Air Force | B7: -259345.94
A8: Missing Cost on PO FA568522F0091 | B8: -259345.94
A9: Federal Army Enterprise | B9: -53647
A10: Sent Email for missing Cost in May 6/14/23 | B10: -53647
A11: Federal Citizen Services | B11: 106778.22
A12: Accrued Missing WWT Cost PO 1CDATA-22-C-0113_3 for proper recognition | B12: -216130.58
A13: FCN EA Cost Deferral - CG emailed 11/15, possibly need vendor credit. Pricing correct see CMG email 11/17, 6/15, 11/13 | B13: 322908.8
A14: Federal COCOMs | B14: 235689.25
A15: Avg cost correction - SO 10811548 Part GSCUSTFCD | B15: 235689.25
A16: Federal Healthcare | B16: -142985
... A34: Grand Total | B34: 2909974.3

Sheet FEB-24
A4: Row Labels | B4: Sum of Entered Amount
A5: Federal AF/DISA/DA House | B5: -771663.59
A6: Termination Fee to be paid by EOY | B6: -771663.59
A7: Federal Air Force | B7: -259345.94
A8: Missing Cost on PO FA568522F0091 | B8: -259345.94
A9: Federal Army Enterprise | B9: -53647
A10: Sent Email for missing Cost in May 6/14/23 | B10: -53647
A11: Federal Citizen Services | B11: 106778.22
A12: Accrued Missing WWT Cost PO 1CDATA-22-C-0113_3 for proper recognition | B12: -216130.58
A13: FCN EA Cost Deferral - CG emailed 11/15, possibly need vendor credit. Pricing correct see CMG email 11/17, 6/15, 11/13 | B13: 322908.8
A14: Federal COCOMs | B14: 235689.25
A15: Avg cost correction - SO 10811548 Part GSCUSTFCD | B15: 235689.25
A16: Federal Healthcare | B16: -128000
... A43: Grand Total | B43: 1591395.9

Sheet MAR-24
A1: World Wide Technology
A2: Accrued Liabilities - Public Sector
A3: ON-PREM G/L # 01.XXXX.24521.000
A4: CLOUD GL# 101.XXXXX.245011.XXXX.XXX.XXX.XXXX.XXXX
A5: 45382
A7: Row Labels | B7: Sum of Functional Amount | C7: Sum of Global Amount
A8: Federal Air Force | B8: -259345.94 | C8: -259345.94
A9: Issue: AP Correction Needed | B9: -259345.94 | C9: -259345.94
A10: Federal Army Enterprise | B10: -53647 | C10: -53647
A11: Issue: AP Correction Needed | B11: -53647 | C11: -53647
A12: Federal Citizen Services | B12: 106778.22 | C12: 106778.22
A13: Accrual: Dropship | B13: -216130.58 | C13: -216130.58
A14: Issue: Ops correction Needed - Pricing | B14: 322908.8 | C14: 322908.8
A15: Federal COCOMs | B15: 385175.84 | C15: 385175.84
A16: Timing: Average Cost Streamline | B16: 149486.59 | C16: 149486.59
A17: Timing: Drop Ship Average Cost - Month End | B17: 235689.25 | C17: 235689.25
A18: Federal Healthcare | B18: -128000 | C18: -128000
A19: Issue: AP Correction Needed | B19: -128000 | C19: -128000
... A43: Grand Total | B43: 1899197.2 | C43: 1899197.2

Sheet JUL-24
A1: World Wide Technology
A2: Accrued Liabilities - Public Sector
A3: ON-PREM G/L # 01.XXXX.24521.000
A4: CLOUD GL# 101.XXXXX.245011.XXXX.XXX.XXX.XXXX.XXXX
A5: 45504
A7: Row Labels | B7: Sum of Functional Amount | C7: Sum of Global Amount
A8: Federal Citizen Services | B8: 322908.8 | C8: 322908.8
A9: Issue: Ops correction Needed - Pricing | B9: 322908.8 | C9: 322908.8
A10: Federal Healthcare | B10: 617055.74 | C10: 617055.74
A11: Issue: AP Correction Needed | B11: -128000 | C11: -128000
A12: Timing: Order on Hold | B12: 745055.74 | C12: 745055.74
A13: Federal Law Enforcement | B13: 925397.64 | C13: 925397.64
A14: Issue: AP Correction Needed | B14: 966837.04 | C14: 966837.04
A15: Timing: Order on Hold | B15: -41439.4 | C15: -41439.4
A16: SLED Southeast | B16: 137760 | C16: 137760
A17: Issue: AP Correction Needed | B17: 137760 | C17: 137760
A18: SLED Central | B18: 635780.08 | C18: 635780.08
A19: Issue: Needs Research | B19: 635780.08 | C19: 635780.08
... A26: Grand Total | B26: 3209618.8 | C26: 3209618.8

Sheet AUG-24
A1: World Wide Technology
A2: Accrued Liabilities - Public Sector
A3: ON-PREM G/L # 01.XXXX.24521.000
A4: CLOUD GL# 101.XXXXX.245011.XXXX.XXX.XXX.XXXX.XXXX
A5: 45535
A7: Row Labels | B7: Sum of Functional Amount | C7: Sum of Global Amount
A8: Federal Army Enterprise | B8: 452022.2 | C8: 452022.2
A9: Issue: AP Correction Needed | B9: 452022.2 | C9: 452022.2
A10: Federal Citizen Services | B10: 322908.8 | C10: 322908.8
A11: Issue: Ops correction Needed - Pricing | B11: 322908.8 | C11: 322908.8
A12: Federal COCOMs | B12: -2702135.8 | C12: -2702135.8
A13: Issue: AP Correction Needed | B13: -2702135.8 | C13: -2702135.8
A14: Federal Healthcare | B14: 8822647.4 | C14: 8822647.4
A15: Issue: AP Correction Needed | B15: -128000 | C15: -128000
A16: Timing: Order on Hold | B16: 745055.74 | C16: 745055.74
A17: Issue: Needs Research | B17: 771150 | C17: 771150
A18: Timing: Prelim Deferral | B18: 7434441.7 | C18: 7434441.7
A19: Federal Law Enforcement | B19: 925397.64 | C19: 925397.64
... A41: Grand Total | B41: -562970.29 | C41: -562970.29

Sheet SEP-24
A1: World Wide Technology
A2: Accrued Liabilities - Public Sector
A3: ON-PREM G/L # 01.XXXX.24521.000
A4: CLOUD GL# 101.XXXXX.245011.XXXX.XXX.XXX.XXXX.XXXX
A5: 45565
A7: Row Labels | B7: Sum of Functional Amount | C7: Sum of Global Amount
A8: Federal Army Enterprise | B8: 222306 | C8: 222306
A9: Issue: AP Correction Needed | B9: 222306 | C9: 222306
A10: Federal Healthcare | B10: -203000 | C10: -203000
A11: Accrual: Dropship | B11: -75000 | C11: -75000
A12: Issue: AP Correction Needed | B12: -128000 | C12: -128000
A13: Federal Law Enforcement | B13: 925397.64 | C13: 925397.64
A14: Issue: AP Correction Needed | B14: 966837.04 | C14: 966837.04
A15: Timing: Order on Hold | B15: -41439.4 | C15: -41439.4
A16: SLED Southeast | B16: 99705.5 | C16: 99705.5
A17: Issue: AP Correction Needed | B17: 137760 | C17: 137760
A18: Issue: Needs Research | B18: -38054.5 | C18: -38054.5
A19: SLED Central | B19: 67500 | C19: 67500
... A37: Grand Total | B37: -6955854.4 | C37: -6955854.4

Sheet OCT-24
A1: World Wide Technology
A2: Accrued Liabilities - Public Sector
A3: ON-PREM G/L # 01.XXXX.24521.000
A4: CLOUD GL# 101.XXXXX.245011.XXXX.XXX.XXX.XXXX.XXXX
A5: 45596
A7: Row Labels | B7: Sum of Functional Amount | C7: Sum of Global Amount
A8: Federal Army Enterprise | B8: 44461.2 | C8: 44461.2
A9: Issue: AP Correction Needed | B9: 44461.2 | C9: 44461.2
A10: Federal Healthcare | B10: -71467382 | C10: -71467382
A11: Accrual: Dropship | B11: -75000 | C11: -75000
A12: Issue: AP Correction Needed | B12: -128000 | C12: -128000
A13: Issue: Needs Research | B13: -71264382 | C13: -71264382
A14: Federal Law Enforcement | B14: 925397.64 | C14: 925397.64
A15: Issue: AP Correction Needed | B15: 966837.04 | C15: 966837.04
A16: Timing: Order on Hold | B16: -41439.4 | C16: -41439.4
A17: SLED Southeast | B17: -440435.86 | C17: -440435.86
A18: Issue: AP Correction Needed | B18: 137760 | C18: 137760
A19: Issue: Needs Research | B19: -38054.5 | C19: -38054.5
... A41: Grand Total | B41: -71151671 | C41: -71151671

Sheet DEC-24
A1: World Wide Technology
A2: Accrued Liabilities - Public Sector
A3: ON-PREM G/L # 01.XXXX.24521.000
A4: CLOUD GL# 101.XXXXX.245011.XXXX.XXX.XXX.XXXX.XXXX
A5: 45657
A7: Row Labels | B7: Sum of Functional Amount | C7: Sum of Global Amount
A8: Federal Army Enterprise | B8: 44461.2 | C8: 44461.2
A9: Issue: AP Correction Needed | B9: 44461.2 | C9: 44461.2
A10: Federal Healthcare | B10: 92075.4 | C10: 92075.4
A11: Accrual: Dropship | B11: -75000 | C11: -75000
A12: Timing: Order on Hold | B12: 167075.4 | C12: 167075.4
A13: SLED Southeast | B13: -578195.86 | C13: -578195.86
A14: Issue: AP Correction Needed | B14: -38054.5 | C14: -38054.5
A15: Timing: Streamline | B15: -540141.36 | C15: -540141.36
A16: Federal DoN Tactical | B16: -227442.19 | C16: -227442.19
A17: Issue: AP Correction Needed | B17: 64668 | C17: 64668
A18: Issue: Needs Research | B18: -292110.19 | C18: -292110.19
A19: SLED HI/Comm | B19: 67751.16 | C19: 67751.16
... A36: Grand Total | B36: 1125063 | C36: 1125063

Sheet JAN-25
A1: World Wide Technology
A2: Accrued Liabilities - Public Sector
A3: ON-PREM G/L # 01.XXXX.24521.000
A4: CLOUD GL# 101.XXXXX.245011.XXXX.XXX.XXX.XXXX.XXXX
A5: 45688
A7: Row Labels | B7: Sum of Functional Amount | C7: Sum of Global Amount
A8: Federal Army Enterprise | B8: 44461.2 | C8: 44461.2
A9: Issue: AP Correction Needed | B9: 44461.2 | C9: 44461.2
A10: Federal Healthcare | B10: 92075.4 | C10: 92075.4
A11: Accrual: Dropship | B11: -75000 | C11: -75000
A12: Timing: Order on Hold | B12: 167075.4 | C12: 167075.4
A13: SLED Southeast | B13: -540141.36 | C13: -540141.36
A14: Timing: Streamline | B14: -540141.36 | C14: -540141.36
A15: Federal DoN Tactical | B15: -227442.19 | C15: -227442.19
A16: Issue: AP Correction Needed | B16: 64668 | C16: 64668
A17: Issue: Needs Research | B17: -292110.19 | C17: -292110.19
A18: Federal Intel | B18: -735360 | C18: -735360
A19: Timing: Streamline | B19: -735360 | C19: -735360
... A28: Grand Total | B28: -1040202.4 | C28: -1040202.4

Sheet FEB-25
A1: World Wide Technology
A2: Accrued Liabilities - Public Sector
A3: ON-PREM G/L # 01.XXXX.24521.000
A4: CLOUD GL# 101.XXXXX.245011.XXXX.XXX.XXX.XXXX.XXXX
A5: 45716
A7: Row Labels | B7: Sum of Functional Amount | C7: Sum of Global Amount
A8: Federal Army Enterprise | B8: 29640.8 | C8: 29640.8
A9: Issue: AP Correction Needed | B9: 29640.8 | C9: 29640.8
A10: Federal Healthcare | B10: 92075.4 | C10: 92075.4
A11: Accrual: Dropship | B11: -75000 | C11: -75000
A12: Timing: Order on Hold | B12: 167075.4 | C12: 167075.4
A13: SLED Southeast | B13: -578195.86 | C13: -578195.86
A14: Issue: AP Correction Needed | B14: -38054.5 | C14: -38054.5
A15: Timing: Streamline | B15: -540141.36 | C15: -540141.36
A16: Federal DoN Tactical | B16: -227442.19 | C16: -227442.19
A17: Issue: AP Correction Needed | B17: 64668 | C17: 64668
A18: Issue: Needs Research | B18: -292110.19 | C18: -292110.19
A19: SLED HI/Comm | B19: -659 | C19: -659
... A36: Grand Total | B36: -657554.44 | C36: -657554.44

Sheet MAR-25
A1: World Wide Technology
A2: Accrued Liabilities - Public Sector
A3: ON-PREM G/L # 01.XXXX.24521.000
A4: CLOUD GL# 101.XXXXX.245011.XXXX.XXX.XXX.XXXX.XXXX
A5: 45747
A7: Row Labels | B7: Sum of Functional Amount | C7: Sum of Global Amount
A8: SLED Southeast | B8: -578195.86 | C8: -578195.86
A9: Issue: AP Correction Needed | B9: -38054.5 | C9: -38054.5
A10: Timing: Streamline | B10: -540141.36 | C10: -540141.36
A11: Federal DoN Tactical | B11: -227442.19 | C11: -227442.19
A12: Issue: AP Correction Needed | B12: 64668 | C12: 64668
A13: Issue: Needs Research | B13: -292110.19 | C13: -292110.19
A14: Federal Intel | B14: -635360 | C14: -635360
A15: Issue: AP Correction Needed | B15: 100000 | C15: 100000
A16: Timing: Streamline | B16: -735360 | C16: -735360
A17: SLED California | B17: 881922.6 | C17: 881922.6
A18: Issue: AR Correction Needed | B18: 881922.6 | C18: 881922.6
A19: Federal Law Enforcement | B19: -2105.77 | C19: -2105.77
... A25: Grand Total | B25: -687204.53 | C25: -687204.53
A40: Total | B40: =GETPIVOTDATA("Sum of Functional Amount",$A$7) -> -687204.53
A42: G/L Balance - USD | B42: -628826.53
A44: Variance | B44: =B40-B42 -> -58378
A46: Date Reconciled | B46: 45761

Sheet APR-25
A1: World Wide Technology
A2: Accrued Liabilities - Public Sector
A3: ON-PREM G/L # 01.XXXX.24521.000
A4: CLOUD GL# 101.XXXXX.245011.XXXX.XXX.XXX.XXXX.XXXX
A5: 45777
A7: Row Labels | B7: Sum of Functional Amount | C7: Sum of Global Amount | E7: Total | F7: =GETPIVOTDATA("Sum of Functional Amount",$A$7) -> #REF!
A8: SLED Southeast | B8: -578195.86 | C8: -578195.86
A9: Issue: AP Correction Needed | B9: -38054.5 | C9: -38054.5 | E9: G/L Balance - USD | F9: -475136.12
A10: Timing: Streamline | B10: -540141.36 | C10: -540141.36
A11: Federal DoN Tactical | B11: -227442.19 | C11: -227442.19 | E11: Variance | F11: =F7-F9 -> #REF!
A12: Issue: AP Correction Needed | B12: 64668 | C12: 64668
A13: Issue: Needs Research | B13: -292110.19 | C13: -292110.19 | E13: Date Reconciled | F13: 45791
A14: Federal Intel | B14: -435362 | C14: -435362
A15: Issue: AP Correction Needed | B15: 100000 | C15: 100000
A16: Timing: Order on Hold | B16: 199998 | C16: 199998
A17: Timing: Streamline | B17: -735360 | C17: -735360
A18: SLED California | B18: 881922.6 | C18: 881922.6
A19: Issue: AR Correction Needed | B19: 881922.6 | C19: 881922.6
A20: Federal USAF/USSF | B20: -5029.46 | C20: -5029.46
A21: Timing: Order on Hold | B21: -5029.46 | C21: -5029.46
A22: Federal Law Enforcement | B22: -2105.77 | C22: -2105.77
A23: Issue: Needs Research | B23: -2105.77 | C23: -2105.77
A24: Federal Army House | B24: -1293.75 | C24: -1293.75
A25: Issue: Needs Research | B25: -1293.75 | C25: -1293.75
... A34: Grand Total | B34: -475136.12 | C34: -475136.12

Sheet MAY-25
A1: World Wide Technology
A2: Accrued Liabilities - Public Sector
A3: ON-PREM G/L # 01.XXXX.24521.000
A4: CLOUD GL# 101.XXXXX.245011.XXXX.XXX.XXX.XXXX.XXXX
A5: 45808
A7: Row Labels | B7: Sum of Functional Amount | C7: Sum of Global Amount | E7: Total | F7: =SUMIFS(B8:B143,A8:A143,"Grand Total") -> -1482537.5
A8: SLED Southeast | B8: -578195.86 | C8: -578195.86
A9: Issue: AP Correction Needed | B9: -38054.5 | C9: -38054.5 | E9: G/L Balance - USD | F9: -1482537.5
A10: Timing: Streamline | B10: -540141.36 | C10: -540141.36
A11: Federal DoN Tactical | B11: -112410.73 | C11: -112410.73 | E11: Variance | F11: =F7-F9 -> 0
A12: Issue: AP Correction Needed | B12: 64668 | C12: 64668
A13: Issue: Needs Research | B13: -292110.19 | C13: -292110.19 | E13: Date Reconciled | F13: 45817
A14: Issue: Recvue AR Correction Needed | B14: 115031.46 | C14: 115031.46
A15: Federal Intel | B15: -635360 | C15: -635360
A16: Issue: AP Correction Needed | B16: 100000 | C16: 100000
A17: Timing: Order on Hold | B17: 0 | C17: 0
A18: Timing: Streamline | B18: -735360 | C18: -735360
A19: - | B19: 0 | C19: 0
A20: SLED California | B20: 881922.6 | C20: 881922.6
A21: Issue: AR Correction Needed | B21: 881922.6 | C21: 881922.6
A22: Federal USAF/USSF | B22: -1420584.2 | C22: -1420584.2
A23: Issue: AP Correction Needed | B23: -1415554.7 | C23: -1415554.7
A24: Timing: Order on Hold | B24: -5029.46 | C24: -5029.46
A25: Federal Law Enforcement | B25: -2105.77 | C25: -2105.77
... A40: Issue: AP Correction Needed | B40: -613137.44 | C40: -613137.44
A41: (blank)
A42: (blank)
A43: Grand Total | B43: -1482537.5 | C43: -1482537.5

Sheet JUN-25
A1: World Wide Technology
A2: Accrued Liabilities - Public Sector
A3: ON-PREM G/L # 01.XXXX.24521.000
A4: CLOUD GL# 101.XXXXX.245011.XXXX.XXX.XXX.XXXX.XXXX
A5: 45838
A7: Row Labels | B7: Sum of Functional Amount | C7: Sum of Global Amount | E7: Total | F7: =SUMIFS(B8:B143,A8:A143,"Grand Total") -> -974487.28
A8: SLED Southeast | B8: -578195.86 | C8: -578195.86
A9: Issue: AP Correction Needed | B9: -38054.5 | C9: -38054.5 | E9: G/L Balance - USD | F9: -974487.28
A10: Timing: Streamline | B10: -540141.36 | C10: -540141.36
A11: Federal DoN Tactical | B11: -227442.19 | C11: -227442.19 | E11: Variance | F11: =F7-F9 -> 0
A12: Issue: AP Correction Needed | B12: 64668 | C12: 64668
A13: Issue: Needs Research | B13: -292110.19 | C13: -292110.19 | E13: Date Reconciled | F13: 45848
A14: Issue: Recvue AR Correction Needed | B14: 0 | C14: 0
A15: Federal Intel | B15: -635360 | C15: -635360
A16: Issue: AP Correction Needed | B16: 100000 | C16: 100000
A17: Timing: Streamline | B17: -735360 | C17: -735360
A18: SLED California | B18: 736168.8 | C18: 736168.8
A19: Issue: AP Correction Needed | B19: -145753.8 | C19: -145753.8
A20: Issue: AR Correction Needed | B20: 881922.6 | C20: 881922.6
A21: Federal USAF/USSF | B21: -649632.76 | C21: -649632.76
A22: Issue: AP Correction Needed | B22: -644603.3 | C22: -644603.3
A23: Timing: Order on Hold | B23: -5029.46 | C23: -5029.46
A24: Federal Law Enforcement | B24: -2105.77 | C24: -2105.77
A25: Issue: Needs Research | B25: -2105.77 | C25: -2105.77
... A34: Issue: AP Correction Needed | B34: -613137.44 | C34: -613137.44
A35: (blank)
A36: (blank)
A37: Federal Defense Agencies | B37: -2115.92 | C37: -2115.92
A38: Timing: Order on Hold | B38: -2115.92 | C38: -2115.92
A39: Grand Total | B39: -974487.28 | C39: -974487.28

Sheet JUL-25
A1: World Wide Technology
A2: Accrued Liabilities - Public Sector
A3: ON-PREM G/L # 01.XXXX.24521.000
A4: CLOUD GL# 101.XXXXX.245011.XXXX.XXX.XXX.XXXX.XXXX
A5: 45869
A7: Row Labels | B7: Sum of Functional Amount | C7: Sum of Global Amount | E7: Total | F7: =SUMIFS(B8:B143,A8:A143,"Grand Total") -> -231432.35
A8: SLED Southeast | B8: -578195.86 | C8: -578195.86
A9: Issue: AP Correction Needed | B9: -38054.5 | C9: -38054.5 | E9: G/L Balance - USD | F9: -231432.35
A10: Timing: Streamline | B10: -540141.36 | C10: -540141.36
A11: Federal DoN Tactical | B11: -227442.19 | C11: -227442.19 | E11: Variance | F11: =F7-F9 -> -2.910383e-10
A12: Issue: AP Correction Needed | B12: 64668 | C12: 64668
A13: Issue: Needs Research | B13: -292110.19 | C13: -292110.19 | E13: Date Reconciled | F13: 45883
A14: Federal Intel | B14: 388962.88 | C14: 388962.88
A15: Issue: AP Correction Needed | B15: 100000 | C15: 100000
A16: Timing: Order on Hold | B16: 779202.88 | C16: 779202.88
A17: Timing: Streamline | B17: -490240 | C17: -490240
A18: SLED California | B18: 736168.8 | C18: 736168.8
A19: Issue: AP Correction Needed | B19: -145753.8 | C19: -145753.8
A20: Issue: AR Correction Needed | B20: 881922.6 | C20: 881922.6
A21: Federal USAF/USSF | B21: -649632.76 | C21: -649632.76
A22: Issue: AP Correction Needed | B22: -644603.3 | C22: -644603.3
A23: Timing: Order on Hold | B23: -5029.46 | C23: -5029.46
A24: Federal Law Enforcement | B24: -2105.77 | C24: -2105.77
A25: Issue: Needs Research | B25: -2105.77 | C25: -2105.77
... A41: Grand Total | B41: -231432.35 | C41: -231432.35

Sheet FEB-26
A1: World Wide Technology
A2: Accrued Liabilities - Public Sector
A3: ON-PREM G/L # 01.XXXX.24521.000
A4: CLOUD GL# 101.XXXXX.245011.XXXX.XXX.XXX.XXXX.XXXX
A5: 46081
A7: Row Labels | B7: Sum of Functional Amount | C7: Sum of Global Amount | E7: Total | F7: =SUMIFS(B8:B143,A8:A143,"Grand Total") -> -200536.45
A8: SLED Southeast | B8: -360094.24 | C8: -360094.24
A9: Timing: Streamline | B9: -360094.24 | C9: -360094.24 | E9: G/L Balance - USD | F9: -471599.97
A10: Federal Intel | B10: -346579 | C10: -346579
A11: Timing: Order on Hold | B11: 143661 | C11: 143661 | E11: Variance | F11: =F7-F9 -> 271063.52
A12: Timing: Streamline | B12: -490240 | C12: -490240
A13: SLED California | B13: 881922.6 | C13: 881922.6 | E13: Date Reconciled | F13: 46093
A14: Issue: AR Correction Needed | B14: 881922.6 | C14: 881922.6
A15: Federal Army House | B15: -9056.25 | C15: -9056.25
A16: Issue: AP Correction Needed | B16: -2587.5 | C16: -2587.5
A17: Issue: Needs Research | B17: -6468.75 | C17: -6468.75
A18: Federal Army Tactical | B18: -124729.56 | C18: -124729.56
A19: Issue: AP Correction Needed | B19: -124729.56 | C19: -124729.56
A20: Federal Army Enterprise | B20: 3000 | C20: 3000
A21: Issue: AR Correction Needed | B21: 3000 | C21: 3000
A22: SLED Midwest | B22: -245000 | C22: -245000
A23: Issue: Recvue Needs Research | B23: -245000 | C23: -245000
A24: Grand Total | B24: -200536.45 | C24: -200536.45

Sheet APR-26
A1: World Wide Technology
A2: Accrued Liabilities - Public Sector
A3: ON-PREM G/L # 01.XXXX.24521.000
A4: CLOUD GL# 101.XXXXX.245011.XXXX.XXX.XXX.XXXX.XXXX
A5: 46142
A7: Row Labels | B7: Sum of Functional Amount | C7: Sum of Global Amount | E7: Total | F7: =SUMIFS(B8:B143,A8:A143,"Grand Total") -> 597569.36
A8: SLED Southeast | B8: -360094.24 | C8: -360094.24
A9: Timing: Streamline | B9: -360094.24 | C9: -360094.24 | E9: G/L Balance - USD | F9: 597569.36
A10: Federal Intel | B10: -211949.8 | C10: -211949.8
A11: Issue: AP Correction Needed | B11: 134629.2 | C11: 134629.2 | E11: Variance | F11: =F7-F9 -> 0
A12: Timing: Order on Hold | B12: 143661 | C12: 143661
A13: Timing: Streamline | B13: -490240 | C13: -490240 | E13: Date Reconciled | F13: 46156
A14: SLED California | B14: 881922.6 | C14: 881922.6
A15: Issue: AR Correction Needed | B15: 881922.6 | C15: 881922.6
A16: Federal Army House | B16: -11643.78 | C16: -11643.78
A17: Issue: AP Correction Needed | B17: -2587.5 | C17: -2587.5
A18: Issue: Needs Research | B18: -9056.28 | C18: -9056.28
A19: Federal Army Tactical | B19: -124729.56 | C19: -124729.56
A20: Issue: AP Correction Needed | B20: -124729.56 | C20: -124729.56
A21: Federal Army Enterprise | B21: 98538.95 | C21: 98538.95
A22: Issue: AR Correction Needed | B22: 191538.95 | C22: 191538.95
A23: Accrual: Agent Fee | B23: -93000 | C23: -93000
A24: SLED Midwest | B24: -245000 | C24: -245000
A25: Issue: Recvue Needs Research | B25: -245000 | C25: -245000
... A46: Grand Total | B46: 597569.36 | C46: 597569.36

Sheet MAY-26
A1: World Wide Technology (WWT)
A2: Accrued Liabilities - Public Sector
A3: ON-PREM G/L # 01.XXXX.24521.000
A4: CLOUD GL# 101.XXXXX.245011.XXXX.XXX.XXX.XXXX.XXXX
A5: 46173
A7: Row Labels | B7: Sum of Functional Amount | C7: Sum of Global Amount | E7: Total | F7: =SUMIFS(B8:B143,A8:A143,"Grand Total") -> -13905762
A8: SLED Southeast | B8: -360094.24 | C8: -360094.24
A9: Timing: Streamline | B9: -360094.24 | C9: -360094.24 | E9: G/L Balance - USD | F9: -13905762
A10: Federal Intel | B10: -69629.8 | C10: -69629.8
A11: Issue: AP Correction Needed | B11: 276949.2 | C11: 276949.2 | E11: Variance | F11: =F7-F9 -> 0
A12: Timing: Order on Hold | B12: 143661 | C12: 143661
A13: Timing: Streamline | B13: -490240 | C13: -490240 | E13: Date Reconciled | F13: 46185
A14: SLED California | B14: 881922.6 | C14: 881922.6
A15: Issue: AR Correction Needed | B15: 881922.6 | C15: 881922.6
A16: Federal Army House | B16: -12708351 | C16: -12708351
A17: Issue: AP Correction Needed | B17: -12699295 | C17: -12699295
A18: Issue: Needs Research | B18: -9056.28 | C18: -9056.28
A19: Federal Army Tactical | B19: -124729.56 | C19: -124729.56
A20: Issue: AP Correction Needed | B20: -124729.56 | C20: -124729.56
A21: Federal Army Enterprise | B21: -90000 | C21: -90000
A22: Issue: AR Correction Needed | B22: 3000 | C22: 3000
A23: Accrual: Agent Fee | B23: -93000 | C23: -93000
A24: SLED Midwest | B24: -245000 | C24: -245000
A25: Issue: Recvue Needs Research | B25: -245000 | C25: -245000
... A46: Grand Total | B46: -13905762 | C46: -13905762

Sheet JUN-26
A1: World Wide Technology (WWT)
A2: Accrued Liabilities - Public Sector
A3: ON-PREM G/L # 01.XXXX.24521.000
A4: CLOUD GL# 101.XXXXX.245011.XXXX.XXX.XXX.XXXX.XXXX
A5: 46203
A7: Row Labels | B7: Sum of Functional Amount | C7: Sum of Global Amount | E7: Total | F7: =SUMIFS(B8:B143,A8:A143,"Grand Total") -> -68318647
A8: SLED Southeast | B8: -360094.24 | C8: -360094.24
A9: Timing: Streamline | B9: -360094.24 | C9: -360094.24 | E9: G/L Balance - USD | F9: -68318647
A10: Federal Intel | B10: -346579 | C10: -346579
A11: Issue: AP Correction Needed | B11: 0 | C11: 0 | E11: Variance | F11: =F7-F9 -> 0
A12: Timing: Order on Hold | B12: 143661 | C12: 143661
A13: Timing: Streamline | B13: -490240 | C13: -490240 | E13: Date Reconciled | F13: 46213
A14: SLED California | B14: 413633.27 | C14: 413633.27
A15: Issue: AP Correction Needed | B15: -468289.33 | C15: -468289.33
A16: Issue: AR Correction Needed | B16: 881922.6 | C16: 881922.6
A17: Federal Army House | B17: -7581488.2 | C17: -7581488.2
A18: Issue: AP Correction Needed | B18: -19718940 | C18: -19718940
A19: Issue: Needs Research | B19: -9056.28 | C19: -9056.28
A20: Reclass: Sales Channel Move | B20: 12146508 | C20: 12146508
A21: Federal Army Tactical | B21: -124729.56 | C21: -124729.56
A22: Issue: AP Correction Needed | B22: -124729.56 | C22: -124729.56
A23: Federal Army Enterprise | B23: -90000 | C23: -90000
A24: Issue: AR Correction Needed | B24: 3000 | C24: 3000
A25: Accrual: Agent Fee | B25: -93000 | C25: -93000
... A53: Grand Total | B53: -68318647 | C53: -68318647

Sheet JUL-26
A1: World Wide Technology (WWT)
A2: Accrued Liabilities - Public Sector
A3: ON-PREM G/L # 01.XXXX.24521.000
A4: CLOUD GL# 101.XXXXX.245011.XXXX.XXX.XXX.XXXX.XXXX
A5: 46234
A7: Row Labels | B7: Sum of Functional Amount | C7: Sum of Global Amount | E7: Total | F7: =SUMIFS(B8:B143,A8:A143,"Grand Total") -> 9698734
A8: SLED Southeast | B8: -360094.24 | C8: -360094.24
A9: Timing: Streamline | B9: -360094.24 | C9: -360094.24 | E9: G/L Balance - USD | F9: 9698734
A10: Federal Intel | B10: -14632.92 | C10: -14632.92
A11: Timing: Order on Hold | B11: 143661 | C11: 143661 | E11: Variance | F11: =F7-F9 -> 0
A12: Timing: Streamline | B12: -245120 | C12: -245120
A13: Issue: Recvue Needs Research | B13: 86826.08 | C13: 86826.08 | E13: Date Reconciled | F13: 46244
A14: SLED California | B14: 413633.27 | C14: 413633.27
A15: Issue: AP Correction Needed | B15: -468289.33 | C15: -468289.33
A16: Issue: AR Correction Needed | B16: 881922.6 | C16: 881922.6
A17: Federal Army House | B17: -367481.86 | C17: -367481.86
A18: Issue: AP Correction Needed | B18: -16901059 | C18: -16901059
A19: Issue: Needs Research | B19: -9056.28 | C19: -9056.28
A20: Reclass: Sales Channel Move | B20: 12146508 | C20: 12146508
A21: Issue: Recvue AP Correction Needed | B21: 4396125.7 | C21: 4396125.7
A22: Federal Army Tactical | B22: -124729.56 | C22: -124729.56
A23: Issue: AP Correction Needed | B23: -124729.56 | C23: -124729.56
A24: Federal Army Enterprise | B24: -90000 | C24: -90000
A25: Issue: AR Correction Needed | B25: 3000 | C25: 3000
... A55: Accrual: Dropship | B55: -876000 | C55: -876000
A56: (blank)
A57: (blank)
A58: Grand Total | B58: 9698734 | C58: 9698734

Sheet AUG-26
A1: World Wide Technology (WWT)
A2: Accrued Liabilities - Public Sector
A3: ON-PREM G/L # 01.XXXX.24521.000
A4: CLOUD GL# 101.XXXXX.245011.XXXX.XXX.XXX.XXXX.XXXX
A5: 46265
A7: Row Labels | B7: Sum of Functional Amount | C7: Sum of Global Amount | E7: Total | F7: =SUMIFS(B8:B55,A8:A55,"Grand Total") -> 9611907.9
A8: SLED Southeast | B8: -360094.24 | C8: -360094.24
A9: Timing: Streamline | B9: -360094.24 | C9: -360094.24 | E9: G/L Balance - USD | F9: 9611907.9
A10: Federal Intel | B10: -101459 | C10: -101459
A11: Timing: Order on Hold | B11: 143661 | C11: 143661 | E11: Variance | F11: =F7-F9 -> 0
A12: Timing: Streamline | B12: -245120 | C12: -245120
A13: SLED California | B13: 413633.27 | C13: 413633.27 | E13: Date Reconciled | F13: 46251
A14: Issue: AP Correction Needed | B14: -468289.33 | C14: -468289.33
A15: Issue: AR Correction Needed | B15: 881922.6 | C15: 881922.6
A16: Federal Army House | B16: -367481.86 | C16: -367481.86
A17: Issue: AP Correction Needed | B17: -16901059 | C17: -16901059
A18: Issue: Needs Research | B18: -9056.28 | C18: -9056.28
A19: Reclass: Sales Channel Move | B19: 12146508 | C19: 12146508
A20: Issue: Recvue AP Correction Needed | B20: 4396125.7 | C20: 4396125.7
A21: Federal Army Tactical | B21: -124729.56 | C21: -124729.56
A22: Issue: AP Correction Needed | B22: -124729.56 | C22: -124729.56
A23: Federal Army Enterprise | B23: -90000 | C23: -90000
A24: Issue: AR Correction Needed | B24: 3000 | C24: 3000
A25: Accrual: Agent Fee | B25: -93000 | C25: -93000
... A55: Grand Total | B55: 9611907.9 | C55: 9611907.9

Sheet Details
D1: Offsets
D2: To be worked in APR-24
D3: Action item for APR-24
D4: Mutli JE's
L5: =SUBTOTAL(9,L7:L1048576) -> 9698734
A6: Age | B6: Aging Bucket | C6: CA Manager Comments | D6: Cost Accountant Comments | E6: Analyst | F6: P And L Name Curr | G6: Je Batch Name | H6: Je Name | I6: Je Reason Code | J6: Gl Period Name | K6: Entered Amount | L6: Functional Amount | M6: Global Amount | N6: Currency Code Entered | O6: Currency Code Functional | P6: Description Header | Q6: Description Line | R6: Company Name Curr | S6: Financial Program Curr | T6: Sub Program Curr | U6: P And L Rollup Curr | V6: Concatenated Segments | W6: Company Code | X6: P And L Code | Y6: Account Code | Z6: Cost Cntr Code | AA6: Gl Location Code | AB6: Gl Intercompany Code | AC6: Future1 Code | AD6: Future2 Code | AE6: Account Name Curr | AF6: WWT Po Number | AG6: WWT Po Description | AH6: WWT Source | AI6: Transaction Date | AJ6: Transaction Number | AK6: Je Effective Date | AL6: Je Source | AM6: Ledger Name
A7: =TODAY()-AK7 -> 657 | B7: =IFERROR(VLOOKUP(A7,'Aging Formulas'!A:B,2,FALSE),"365+") -> 365+ | D7: Streamline PO GDIT-33088 General Dynamics Information Tech - Releasing 2026 & 2027 | E7: Fienup, Mary Frances | F7: Federal Intel | G7: TJM-110424-11 Streamline PO GDIT-33088 General Dynamics Information Tech Reverse Year 422 22800007 N | H7: TJM-110424-11 Streamline PO GDIT-33088 General Dynamics Information Tech Reverse Year 5 2027 225358 | I7: Timing: Streamline | J7: Oct-24 | K7: -245120 | L7: -245120 | M7: -245120 | N7: USD | O7: USD | P7: Streamlining PO GDIT-33088 WWTNCSAAS1270 - Cisco credit 6101578249 given in year 1 and year 2 streamlining over the 5 year deal | Q7: Journal Import Created | R7: World Wide Technology, LLC (WWT) | S7: Public Sector | T7: Federal | U7: Federal IC | V7: 101.12012.245011.9999.999.999.9999.9999 | W7: 101 | X7: 12012 | Y7: 245011 | Z7: 9999 | AA7: 999 | AB7: 999 | AC7: 9999 | AD7: 9999 | AE7: Accrued Liabilities - Public Sector | AF7: - | AG7: - | AH7: CLOUD | AJ7: - | AK7: 45594 | AL7: EBS OPR | AM7: WWT US Ledger
A8: =TODAY()-AK8 -> 655 | B8: =IFERROR(VLOOKUP(A8,'Aging Formulas'!A:B,2,FALSE),"365+") -> 365+ | D8: Streamline PO Y25AMW0050 UNC at Chapel Hill Reverse - Releasing 2026 & 2027 | E8: Simms, Amanda | F8: SLED Southeast | G8: TJM-110524-5 Streamline PO Y25AMW0050 UNC at Chapel Hill Reverse Year 4 2027 05-NOV-2024 22800004 N | H8: TJM-110524-5 Streamline PO Y25AMW0050 UNC at Chapel Hill Reverse Year 4 2027 OPR Adjustments | I8: Timing: Streamline | J8: Oct-24 | K8: -180047.12 | L8: -180047.12 | M8: -180047.12 | N8: USD | O8: USD | P8: Streamline PO Y25AMW0050 UNC at Chapel Hill Reverse Year 4 2027 | Q8: Journal Import Created | R8: World Wide Technology, LLC (WWT) | S8: Public Sector | T8: SLED | U8: SLED East | V8: 101.13008.245011.9999.999.999.9999.9999 | W8: 101 | X8: 13008 | Y8: 245011 | Z8: 9999 | AA8: 999 | AB8: 999 | AC8: 9999 | AD8: 9999 | AE8: Accrued Liabilities - Public Sector | AF8: - | AG8: - | AH8: CLOUD | AJ8: - | AK8: 45596 | AL8: EBS OPR | AM8: WWT US Ledger
A9: =TODAY()-AK9 -> 655 | B9: =IFERROR(VLOOKUP(A9,'Aging Formulas'!A:B,2,FALSE),"365+") -> 365+ | D9: Streamline PO Y25AMW0050 UNC at Chapel Hill Reverse - Releasing 2026 & 2027 | E9: Simms, Amanda | F9: SLED Southeast | G9: TJM-110524-4 Streamline PO Y25AMW0050 UNC at Chapel Hill Reverse Year 3 2026 05-NOV-2024 22800004 N | H9: TJM-110524-4 Streamline PO Y25AMW0050 UNC at Chapel Hill Reverse Year 3 2026 OPR Adjustments | I9: Timing: Streamline | J9: Oct-24 | K9: -180047.12 | L9: -180047.12 | M9: -180047.12 | N9: USD | O9: USD | P9: Streamline PO Y25AMW0050 UNC at Chapel Hill Reverse Year 3 2026 | Q9: Journal Import Created | R9: World Wide Technology, LLC (WWT) | S9: Public Sector | T9: SLED | U9: SLED East | V9: 101.13008.245011.9999.999.999.9999.9999 | W9: 101 | X9: 13008 | Y9: 245011 | Z9: 9999 | AA9: 999 | AB9: 999 | AC9: 9999 | AD9: 9999 | AE9: Accrued Liabilities - Public Sector | AF9: - | AG9: - | AH9: CLOUD | AJ9: - | AK9: 45596 | AL9: EBS OPR | AM9: WWT US Ledger
A10: =TODAY()-AK10 -> 594 | B10: =IFERROR(VLOOKUP(A10,'Aging Formulas'!A:B,2,FALSE),"365+") -> 365+ | D10: Correcting or taking hit by Sep-26 - Deferred SO 11858312 PO 19537991-0-CAP out of Dec - working with team to address missing cost | E10: Simms, Amanda | F10: SLED California | G10: TJM-010725-8 Defer SO 11858312 PO 19537991-0-CAP out of Dec-24 07-JAN-2025 12:59:48 EBS O 23865721 N | H10: TJM-010725-8 Defer SO 11858312 PO 19537991-0-CAP out of Dec-24 OPR Adjustments | I10: Issue: AR Correction Needed | J10: Dec-24 | K10: 881922.6 | L10: 881922.6 | M10: 881922.6 | N10: USD | O10: USD | P10: Defer SO 11858312 PO 19537991-0-CAP out of Dec-24 | Q10: Journal Import Created | R10: World Wide Technology, LLC (WWT) | S10: Public Sector | T10: SLED | U10: SLED West | V10: 101.13016.245011.9999.999.999.9999.9999 | W10: 101 | X10: 13016 | Y10: 245011 | Z10: 9999 | AA10: 999 | AB10: 999 | AC10: 9999 | AD10: 9999 | AE10: Accrued Liabilities - Public Sector | AF10: - | AG10: - | AH10: CLOUD | AJ10: - | AK10: 45657 | AL10: EBS OPR | AM10: WWT US Ledger
A11: =TODAY()-AK11 -> 563 | B11: =IFERROR(VLOOKUP(A11,'Aging Formulas'!A:B,2,FALSE),"365+") -> 365+ | D11: Reviewing with Stephanie - related to SEWP Fees - Deferred AP invoice - researching | E11: Maggi, Brandon | F11: Federal Army House | G11: TJM-020625-3 Deferring AP Invoice out of Jan-25 Spreadsheet A 300000305300838 24387210 N | H11: TJM-020625-3 Deferring AP Invoice out of Jan-25 Adjustment | I11: Issue: Needs Research | J11: Jan-25 | K11: -1293.75 | L11: -1293.75 | M11: -1293.75 | N11: USD | O11: USD | P11: Deferring AP Invoice out of Jan-25 | Q11: Journal Import Created | R11: World Wide Technology, LLC (WWT) | S11: Public Sector | T11: Federal | U11: Federal Department of Defense | V11: 101.11002.245011.9999.999.999.9999.9999 | W11: 101 | X11: 11002 | Y11: 245011 | Z11: 9999 | AA11: 999 | AB11: 999 | AC11: 9999 | AD11: 9999 | AE11: Accrued Liabilities - Public Sector | AF11: - | AG11: - | AH11: CLOUD | AJ11: - | AK11: 45688 | AL11: Spreadsheet | AM11: WWT US Ledger
A12: =TODAY()-AK12 -> 504 | B12: =IFERROR(VLOOKUP(A12,'Aging Formulas'!A:B,2,FALSE),"365+") -> 365+ | D12: Reviewing with Stephanie - Deferring AP Invoices Coded to Incorrect Account | E12: Maggi, Brandon | F12: Federal Army Tactical | G12: TJM-040425-9 Deferring AP Invoices Coded to Incorrect Account Spreadsheet A 3000003053008 25423574 N | H12: TJM-040425-9 Deferring AP Invoices Coded to Incorrect Account Adjustment | I12: Issue: AP Correction Needed | J12: Mar-25 | K12: -103941.3 | L12: -103941.3 | M12: -103941.3 | N12: USD | O12: USD | P12: Deferring AP Invoices Coded to Incorrect Account X05635750101CMRECLASS | Q12: Journal Import Created | R12: World Wide Technology, LLC (WWT) | S12: Public Sector | T12: Federal | U12: Federal Department of Defense | V12: 101.11004.245011.9999.999.999.9999.9999 | W12: 101 | X12: 11004 | Y12: 245011 | Z12: 9999 | AA12: 999 | AB12: 999 | AC12: 9999 | AD12: 9999 | AE12: Accrued Liabilities - Public Sector | AF12: P010282017 | AG12: - | AH12: CLOUD | AJ12: - | AK12: 45747 | AL12: Spreadsheet | AM12: WWT US Ledger
A13: =TODAY()-AK13 -> 504 | B13: =IFERROR(VLOOKUP(A13,'Aging Formulas'!A:B,2,FALSE),"365+") -> 365+ | D13: Reviewing with Stephanie - Deferring AP Invoices Coded to Incorrect Account | E13: Maggi, Brandon | F13: Federal Army Tactical | G13: TJM-040425-9 Deferring AP Invoices Coded to Incorrect Account Spreadsheet A 3000003053008 25423574 N | H13: TJM-040425-9 Deferring AP Invoices Coded to Incorrect Account Adjustment | I13: Issue: AP Correction Needed | J13: Mar-25 | K13: -20788.26 | L13: -20788.26 | M13: -20788.26 | N13: USD | O13: USD | P13: Deferring AP Invoices Coded to Incorrect Account X05635750101CMRECLASS | Q13: Journal Import Created | R13: World Wide Technology, LLC (WWT) | S13: Public Sector | T13: Federal | U13: Federal Department of Defense | V13: 101.11004.245011.9999.999.999.9999.9999 | W13: 101 | X13: 11004 | Y13: 245011 | Z13: 9999 | AA13: 999 | AB13: 999 | AC13: 9999 | AD13: 9999 | AE13: Accrued Liabilities - Public Sector | AF13: P010282017 | AG13: - | AH13: CLOUD | AJ13: - | AK13: 45747 | AL13: Spreadsheet | AM13: WWT US Ledger
A14: =TODAY()-AK14 -> 443 | B14: =IFERROR(VLOOKUP(A14,'Aging Formulas'!A:B,2,FALSE),"365+") -> 365+ | D14: Reviewing with Stephanie - related to SEWP Fees - Deferred AP invoice - researching | E14: Maggi, Brandon | F14: Federal Army House | G14: TJM-060525-16 Deferring AP Invoice out of May-25 | H14: TJM-060525-16 Deferring AP Invoice out of May-25 | I14: Issue: AP Correction Needed | J14: May-25 | K14: -1293.75 | L14: -1293.75 | M14: -1293.75 | N14: USD | O14: USD | P14: Deferring AP Invoice out of May-25 | Q14: - | R14: World Wide Technology, LLC (WWT) | S14: Public Sector | T14: Federal | U14: Federal Department of Defense | V14: 101.11002.245011.9999.950.999.9999.9999 | W14: 101 | X14: 11002 | Y14: 245011 | Z14: 9999 | AA14: 950 | AB14: 999 | AC14: 9999 | AD14: 9999 | AE14: Accrued Liabilities - Public Sector | AF14: HC108421F0175 | AG14: - | AH14: CLOUD | AJ14: - | AK14: 45808 | AL14: Manual | AM14: WWT US Ledger
